<?xml version="1.0" ?>
<!-- =================================================================================== -->
<!-- |    This document was autogenerated by xacro from /home/jweisz/curg/staubli_ws/src/staubli_barretthand_description/robots/staubli_bhand.xacro | -->
<!-- |    EDITING THIS FILE BY HAND IS NOT RECOMMENDED                                 | -->
<!-- =================================================================================== -->
<robot name="staubli_bhand" xmlns:controller="http://playerstage.sourceforge.net/gazebo/xmlschema/#controller" xmlns:xacro="http://ros.org/wiki/xacro">
  <!-- Calibration for arm to barrett hand -->
  <!-- Include staubli robot -->
  <!-- Include all the WAM stuff -->
  <material name="WAMGrey">
    <color rgba="0.7 0.7 0.7 1.0"/>
  </material>
  <!-- Include the barrett hands mount on the staubli -->
  <link name="staubli_rx60l_link1">
    <visual>
      <origin rpy="0 0 0" xyz="0 0 0"/>
      <geometry>
        <mesh filename="package://staubli/meshes/rx60l/visual/rx60bl_hb.dae" scale="0.001 0.001 0.001"/>
      </geometry>
      <material name="Yellow">
        <color rgba="245 196 0 1.0"/>
      </material>
    </visual>
    <collision>
      <origin rpy="0 0 0" xyz="0 0 0"/>
      <geometry>
        <mesh filename="package://staubli/meshes/rx60l/collision/rx60bl_hb.stl" scale="0.001 0.001 0.001"/>
      </geometry>
      <material name="Blue">
        <color rgba="0 0 255 1.0"/>
      </material>
    </collision>
  </link>
  <link name="staubli_rx60l_link2">
    <visual>
      <origin rpy="0 0 0" xyz="0 0 0"/>
      <geometry>
        <mesh filename="package://staubli/meshes/rx60l/visual/rx60bl_hb1.dae" scale="0.001 0.001 0.001"/>
      </geometry>
      <material name="Yellow">
        <color rgba="245 196 0 1.0"/>
      </material>
    </visual>
    <collision>
      <origin rpy="0 0 0" xyz="0 0 0"/>
      <geometry>
        <mesh filename="package://staubli/meshes/rx60l/visual/rx60bl_hb1.dae" scale="0.001 0.001 0.001"/>
      </geometry>
      <material name="Green">
        <color rgba="0 0 255 1.0"/>
      </material>
    </collision>
  </link>
  <link name="staubli_rx60l_link3">
    <visual>
      <origin rpy="0 0 0" xyz="0 0 0"/>
      <geometry>
        <mesh filename="package://staubli/meshes/rx60l/visual/rx60bl_hb2.stl" scale="0.001 0.001 0.001"/>
      </geometry>
      <material name="White">
        <color rgba="0 0 255 1.0"/>
      </material>
    </visual>
    <collision>
      <origin rpy="0 0 0" xyz="0 0 0"/>
      <geometry>
        <mesh filename="package://staubli/meshes/rx60l/visual/rx60bl_hb2.stl" scale="0.001 0.001 0.001"/>
      </geometry>
      <material name="Blue">
        <color rgba="0 0 255 1.0"/>
      </material>
    </collision>
  </link>
  <link name="staubli_rx60l_link4">
    <visual>
      <origin rpy="0 0 0" xyz="0 0 0"/>
      <geometry>
        <mesh filename="package://staubli/meshes/rx60l/visual/rx60bl_hb3.dae" scale="0.001 0.001 0.001"/>
      </geometry>
      <material name="Red">
        <color rgba="0 0 255 1.0"/>
      </material>
    </visual>
    <collision>
      <origin rpy="0 0 0" xyz="0 0 0"/>
      <geometry>
        <mesh filename="package://staubli/meshes/rx60l/visual/rx60bl_hb3.dae" scale="0.001 0.001 0.001"/>
      </geometry>
      <material name="Blue">
        <color rgba="0 0 255 1.0"/>
      </material>
    </collision>
  </link>
  <link name="staubli_rx60l_link5">
    <visual>
      <origin rpy="0 0 0" xyz="0 0 0"/>
      <geometry>
        <mesh filename="package://staubli/meshes/rx60l/visual/rx60bl_hb4.dae" scale="0.001 0.001 0.001"/>
      </geometry>
      <material name="Blue">
        <color rgba="0 0 255 1.0"/>
      </material>
    </visual>
    <collision>
      <origin rpy="0 0 0" xyz="0 0 0"/>
      <geometry>
        <mesh filename="package://staubli/meshes/rx60l/visual/rx60bl_hb4.dae" scale="0.001 0.001 0.001"/>
      </geometry>
      <material name="Blue">
        <color rgba="0 0 255 1.0"/>
      </material>
    </collision>
  </link>
  <link name="staubli_rx60l_link6">
    <visual>
      <origin rpy="0 0 0" xyz="0 0 0"/>
      <geometry>
        <mesh filename="package://staubli/meshes/rx60l/visual/rx60bl_hb5.dae" scale="0.001 0.001 0.001"/>
      </geometry>
      <material name="Blue">
        <color rgba="0 0 255 1.0"/>
      </material>
    </visual>
    <collision>
      <origin rpy="0 0 0" xyz="0 0 0"/>
      <geometry>
        <mesh filename="package://staubli/meshes/rx60l/visual/rx60bl_hb5.dae" scale="0.001 0.001 0.001"/>
      </geometry>
      <material name="Blue">
        <color rgba="0 0 255 1.0"/>
      </material>
    </collision>
  </link>
  <link name="staubli_rx60l_link7">
    <visual>
      <origin rpy="0 0 0" xyz="0 0 0"/>
      <geometry>
        <mesh filename="package://staubli/meshes/rx60l/visual/rx60bl_hb6.dae" scale="0.001 0.001 0.001"/>
      </geometry>
      <material name="Gray">
        <color rgba="100 100 100 1.0"/>
      </material>
    </visual>
    <collision>
      <origin rpy="0 0 0" xyz="0 0 0"/>
      <geometry>
        <mesh filename="package://staubli/meshes/rx60l/visual/rx60bl_hb6.dae" scale="0.001 0.001 0.001"/>
      </geometry>
      <material name="Gray">
        <color rgba="100 100 100 1.0"/>
      </material>
    </collision>
  </link>
  <link name="staubli_rx60l_tool0"/>
  <joint name="joint_1" type="revolute">
    <origin xyz="0 0 0"/>
    <parent link="staubli_rx60l_link1"/>
    <child link="staubli_rx60l_link2"/>
    <axis xyz="0 0 1"/>
    <limit effort="100" lower="-2.792526803" upper="2.792526803" velocity="5.009094953"/>
  </joint>
  <joint name="joint_2" type="revolute">
    <origin xyz="0 0 0.341"/>
    <parent link="staubli_rx60l_link2"/>
    <child link="staubli_rx60l_link3"/>
    <axis xyz="0 1 0"/>
    <limit effort="100" lower="-2.225294796" upper="2.225294796" velocity="5.009094953"/>
  </joint>
  <joint name="joint_3" type="revolute">
    <origin xyz="0 0.049 0.400"/>
    <parent link="staubli_rx60l_link3"/>
    <child link="staubli_rx60l_link4"/>
    <axis xyz="0 1 0"/>
    <limit effort="100" lower="-2.347467844" upper="2.347467844" velocity="5.567600314"/>
  </joint>
  <joint name="joint_4" type="revolute">
    <origin xyz="0 0 0"/>
    <parent link="staubli_rx60l_link4"/>
    <child link="staubli_rx60l_link5"/>
    <axis xyz="0 0 1"/>
    <limit effort="100" lower="-4.71238898" upper="4.71238898" velocity="7.155849933"/>
  </joint>
  <joint name="joint_5" type="revolute">
    <origin xyz="0 0 0.400"/>
    <parent link="staubli_rx60l_link5"/>
    <child link="staubli_rx60l_link6"/>
    <axis xyz="0 1 0"/>
    <limit effort="100" lower="-1.911135531" upper="2.103121749" velocity="5.585053606"/>
  </joint>
  <joint name="joint_6" type="revolute">
    <origin xyz="0 0 0.065"/>
    <parent link="staubli_rx60l_link6"/>
    <child link="staubli_rx60l_link7"/>
    <axis xyz="0 0 1"/>
    <limit effort="100" lower="-4.71238898" upper="4.71238898" velocity="12.217304764"/>
  </joint>
  <joint name="joint_6-tool0" type="fixed">
    <parent link="staubli_rx60l_link7"/>
    <child link="staubli_rx60l_tool0"/>
    <origin rpy="0 0 0" xyz="0 0 0"/>
  </joint>
  <link name="wrist_load_cell">
    <visual>
      <material name="ATIGreen">
        <color rgba="0.4 1.0 0.4 1.0"/>
      </material>
      <origin rpy="0 0 0" xyz="0 0 0"/>
      <geometry>
        <cylinder length="0.0775" radius="0.05"/>
      </geometry>
    </visual>
    <collision>
      <material name="ATIGreen">
        <color rgba="0.4 1.0 0.4 1.0"/>
      </material>
      <origin rpy="0 0 0" xyz="0 0 0"/>
      <geometry>
        <cylinder length="0.0775" radius="0.065"/>
      </geometry>
    </collision>
    <inertial>
      <origin xyz="0 0 0"/>
      <mass value="0.50573"/>
      <inertia ixx="0.0001" ixy="0.0" ixz="0.0" iyy="0.0001" iyz="0.0" izz="0.001"/>
    </inertial>
  </link>
  <joint name="ati_load_cell_joint" type="fixed">
    <origin rpy="0 0 0" xyz="0 0 0.03875"/>
    <parent link="staubli_rx60l_link7"/>
    <child link="wrist_load_cell"/>
  </joint>
  <link name="barrett_mount_link">
    <visual>
      <origin rpy="0 0 0" xyz="0.0 0.02 0"/>
      <material name="ATIGreen">
        <color rgba="0.4 1.0 0.4 1.0"/>
      </material>
      <geometry>
        <box size="0.12 0.15 0.03"/>
      </geometry>
    </visual>
    <collision>
      <origin rpy="0 0 0" xyz="0.0 0.02 0"/>
      <material name="ATIGreen">
        <color rgba="0.4 1.0 0.4 1.0"/>
      </material>
      <geometry>
        <cylinder length="0.0775" radius="0.065"/>
      </geometry>
    </collision>
    <inertial>
      <origin xyz="0 0 0"/>
      <mass value="0.50573"/>
      <inertia ixx="0.0001" ixy="0.0" ixz="0.0" iyy="0.0001" iyz="0.0" izz="0.001"/>
    </inertial>
  </link>
  <joint name="barrett_mount_joint" type="fixed">
    <origin rpy="0 0 5.0614" xyz="0 0 0.0625"/>
    <parent link="staubli_rx60l_link7"/>
    <child link="barrett_mount_link"/>
  </joint>
  <joint name="wam/bhand/bhand_base_joint" type="fixed">
    <parent link="staubli_rx60l_link7"/>
    <child link="wam/bhand/bhand_palm_link"/>
    <origin rpy="0 0 5.0614" xyz="0 0 0.0775"/>
  </joint>
  <gazebo reference="wam/bhand/bhand_palm_link">
    <mu1>0.8</mu1>
    <mu2>0.8</mu2>
    <selfCollide>true</selfCollide>
  </gazebo>
  <link name="wam/bhand/bhand_palm_link">
    <inertial>
      <origin xyz="-5.1098e-005 0.0050433 0.036671"/>
      <mass value="0.50573"/>
      <inertia ixx="3.8374e-005" ixy="-5.604e-008" ixz="-4.2034e-005" iyy="0.00022405" iyz="1.3283e-007" izz="0.00020045"/>
    </inertial>
    <visual>
      <material name="WAMGrey">
        <color rgba="0.9 0.9 0.9 0.0"/>
      </material>
      <geometry>
        <mesh filename="package://barrett_model/models/sw_meshes/bhand/bhand_palm_fine.stl"/>
      </geometry>
    </visual>
    <collision>
      <geometry>
        <mesh filename="package://barrett_model/models/sw_meshes/bhand/bhand_palm_link_convex_decomposition.dae"/>
      </geometry>
    </collision>
  </link>
  <joint name="wam/bhand/finger_1/prox_joint" type="revolute">
    <parent link="wam/bhand/bhand_palm_link"/>
    <child link="wam/bhand/finger_1/prox_link"/>
    <origin rpy="0 0 -1.57079632679" xyz="0.025 0.0 0.0415"/>
    <axis xyz="0 0 1"/>
    <limit effort="5" lower="0" upper="3.14159265359" velocity="5.0"/>
    <dynamics damping="1.5" friction="1"/>
  </joint>
  <gazebo reference="wam/bhand/finger_1/prox_joint">
    <provideFeedback>true</provideFeedback>
    <implicitSpringDamper>true</implicitSpringDamper>
  </gazebo>
  <gazebo reference="wam/bhand/finger_1/prox_link">
    <mu1>0.8</mu1>
    <mu2>0.8</mu2>
    <selfCollide>true</selfCollide>
  </gazebo>
  <link name="wam/bhand/finger_1/prox_link">
    <inertial>
      <origin xyz="0.023133 0.00078642 0.00052792"/>
      <mass value="0.14109"/>
      <inertia ixx="4.872e-006" ixy="1.7103e-006" ixz="3.4041e-008" iyy="7.6588e-005" iyz="2.3133e-008" izz="7.7733e-005"/>
    </inertial>
    <visual>
      <material name="WAMGrey">
        <color rgba="0.9 0.9 0.9 0.0"/>
      </material>
      <geometry>
        <mesh filename="package://barrett_model/models/sw_meshes/bhand/bhand_finger_prox_link_fine.stl"/>
      </geometry>
    </visual>
    <collision>
      <geometry>
        <mesh filename="package://barrett_model/models/sw_meshes/bhand/bhand_finger_prox_link_convex_decomposition.dae"/>
      </geometry>
    </collision>
  </link>
  <joint name="wam/bhand/finger_1/med_joint" type="revolute">
    <parent link="wam/bhand/finger_1/prox_link"/>
    <child link="wam/bhand/finger_1/med_link"/>
    <origin rpy="1.57079632679 0 0" xyz="0.05 0.0 0.03390"/>
    <axis xyz="0 0 1"/>
    <limit effort="5" lower="0" upper="2.44346095279" velocity="5.00"/>
    <dynamics damping="1.5" friction="1"/>
  </joint>
  <gazebo reference="wam/bhand/finger_1/med_joint">
    <provideFeedback>true</provideFeedback>
    <implicitSpringDamper>true</implicitSpringDamper>
  </gazebo>
  <gazebo reference="wam/bhand/finger_1/med_link">
    <mu1>0.8</mu1>
    <mu2>0.8</mu2>
    <selfCollide>true</selfCollide>
  </gazebo>
  <link name="wam/bhand/finger_1/med_link">
    <inertial>
      <origin xyz="0.023133 0.00078642 0.00052792"/>
      <mass value="0.062139"/>
      <inertia ixx="4.872e-006" ixy="1.7103e-006" ixz="3.4041e-008" iyy="7.6588e-005" iyz="2.3133e-008" izz="7.7733e-005"/>
    </inertial>
    <visual>
      <material name="WAMGrey">
        <color rgba="0.9 0.9 0.9 0.0"/>
      </material>
      <geometry>
        <mesh filename="package://barrett_model/models/sw_meshes/bhand/bhand_finger_med_link_fine.stl"/>
      </geometry>
    </visual>
    <collision>
      <geometry>
        <mesh filename="package://barrett_model/models/sw_meshes/bhand/bhand_finger_med_link_convex.stl"/>
      </geometry>
    </collision>
  </link>
  <joint name="wam/bhand/finger_1/dist_joint" type="revolute">
    <parent link="wam/bhand/finger_1/med_link"/>
    <child link="wam/bhand/finger_1/dist_link"/>
    <origin rpy="0 0 0" xyz="0.06994 0.003 0.0"/>
    <axis xyz="0 0 1"/>
    <limit effort="5" lower="0" upper="0.837758040957" velocity="5.00"/>
    <dynamics damping="1.5" friction="1"/>
  </joint>
  <gazebo reference="wam/bhand/finger_1/dist_joint">
    <provideFeedback>true</provideFeedback>
    <implicitSpringDamper>true</implicitSpringDamper>
  </gazebo>
  <gazebo reference="wam/bhand/finger_1/dist_link">
    <mu1>0.8</mu1>
    <mu2>0.8</mu2>
    <selfCollide>true</selfCollide>
  </gazebo>
  <link name="wam/bhand/finger_1/dist_link">
    <inertial>
      <origin xyz="0.022825 0.0010491 0.0004203"/>
      <mass value="0.041377"/>
      <inertia ixx="3.1582e-006" ixy="1.4308e-006" ixz="1.0106e-007" iyy="3.8376e-005" iyz="0" izz="3.7275e-005"/>
    </inertial>
    <visual>
      <material name="WAMGrey">
        <color rgba="0.9 0.9 0.9 0.0"/>
      </material>
      <geometry>
        <mesh filename="package://barrett_model/models/sw_meshes/bhand/bhand_finger_dist_link_fine.stl"/>
      </geometry>
    </visual>
    <collision>
      <geometry>
        <mesh filename="package://barrett_model/models/sw_meshes/bhand/bhand_finger_dist_link_convex.stl"/>
      </geometry>
    </collision>
  </link>
  <joint name="wam/bhand/finger_2/prox_joint" type="revolute">
    <parent link="wam/bhand/bhand_palm_link"/>
    <child link="wam/bhand/finger_2/prox_link"/>
    <origin rpy="0 0 -1.57079632679" xyz="-0.025 0.0 0.0415"/>
    <axis xyz="0 0 -1"/>
    <limit effort="5" lower="0" upper="3.14159265359" velocity="5.0"/>
    <dynamics damping="1.5" friction="1"/>
    <mimic joint="wam/bhand/finger_1/prox_joint" multiplier="1.0" offset="0.0"/>
  </joint>
  <gazebo reference="wam/bhand/finger_2/prox_joint">
    <provideFeedback>true</provideFeedback>
    <implicitSpringDamper>true</implicitSpringDamper>
  </gazebo>
  <gazebo reference="wam/bhand/finger_2/prox_link">
    <mu1>0.8</mu1>
    <mu2>0.8</mu2>
    <selfCollide>true</selfCollide>
  </gazebo>
  <link name="wam/bhand/finger_2/prox_link">
    <inertial>
      <origin xyz="0.023133 0.00078642 0.00052792"/>
      <mass value="0.14109"/>
      <inertia ixx="4.872e-006" ixy="1.7103e-006" ixz="3.4041e-008" iyy="7.6588e-005" iyz="2.3133e-008" izz="7.7733e-005"/>
    </inertial>
    <visual>
      <material name="WAMGrey">
        <color rgba="0.9 0.9 0.9 0.0"/>
      </material>
      <geometry>
        <mesh filename="package://barrett_model/models/sw_meshes/bhand/bhand_finger_prox_link_fine.stl"/>
      </geometry>
    </visual>
    <collision>
      <geometry>
        <mesh filename="package://barrett_model/models/sw_meshes/bhand/bhand_finger_prox_link_convex_decomposition.dae"/>
      </geometry>
    </collision>
  </link>
  <joint name="wam/bhand/finger_2/med_joint" type="revolute">
    <parent link="wam/bhand/finger_2/prox_link"/>
    <child link="wam/bhand/finger_2/med_link"/>
    <origin rpy="1.57079632679 0 0" xyz="0.05 0.0 0.03390"/>
    <axis xyz="0 0 1"/>
    <limit effort="5" lower="0" upper="2.44346095279" velocity="5.00"/>
    <dynamics damping="1.5" friction="1"/>
  </joint>
  <gazebo reference="wam/bhand/finger_2/med_joint">
    <provideFeedback>true</provideFeedback>
    <implicitSpringDamper>true</implicitSpringDamper>
  </gazebo>
  <gazebo reference="wam/bhand/finger_2/med_link">
    <mu1>0.8</mu1>
    <mu2>0.8</mu2>
    <selfCollide>true</selfCollide>
  </gazebo>
  <link name="wam/bhand/finger_2/med_link">
    <inertial>
      <origin xyz="0.023133 0.00078642 0.00052792"/>
      <mass value="0.062139"/>
      <inertia ixx="4.872e-006" ixy="1.7103e-006" ixz="3.4041e-008" iyy="7.6588e-005" iyz="2.3133e-008" izz="7.7733e-005"/>
    </inertial>
    <visual>
      <material name="WAMGrey">
        <color rgba="0.9 0.9 0.9 0.0"/>
      </material>
      <geometry>
        <mesh filename="package://barrett_model/models/sw_meshes/bhand/bhand_finger_med_link_fine.stl"/>
      </geometry>
    </visual>
    <collision>
      <geometry>
        <mesh filename="package://barrett_model/models/sw_meshes/bhand/bhand_finger_med_link_convex.stl"/>
      </geometry>
    </collision>
  </link>
  <joint name="wam/bhand/finger_2/dist_joint" type="revolute">
    <parent link="wam/bhand/finger_2/med_link"/>
    <child link="wam/bhand/finger_2/dist_link"/>
    <origin rpy="0 0 0" xyz="0.06994 0.003 0.0"/>
    <axis xyz="0 0 1"/>
    <limit effort="5" lower="0" upper="0.837758040957" velocity="5.00"/>
    <dynamics damping="1.5" friction="1"/>
  </joint>
  <gazebo reference="wam/bhand/finger_2/dist_joint">
    <provideFeedback>true</provideFeedback>
    <implicitSpringDamper>true</implicitSpringDamper>
  </gazebo>
  <gazebo reference="wam/bhand/finger_2/dist_link">
    <mu1>0.8</mu1>
    <mu2>0.8</mu2>
    <selfCollide>true</selfCollide>
  </gazebo>
  <link name="wam/bhand/finger_2/dist_link">
    <inertial>
      <origin xyz="0.022825 0.0010491 0.0004203"/>
      <mass value="0.041377"/>
      <inertia ixx="3.1582e-006" ixy="1.4308e-006" ixz="1.0106e-007" iyy="3.8376e-005" iyz="0" izz="3.7275e-005"/>
    </inertial>
    <visual>
      <material name="WAMGrey">
        <color rgba="0.9 0.9 0.9 0.0"/>
      </material>
      <geometry>
        <mesh filename="package://barrett_model/models/sw_meshes/bhand/bhand_finger_dist_link_fine.stl"/>
      </geometry>
    </visual>
    <collision>
      <geometry>
        <mesh filename="package://barrett_model/models/sw_meshes/bhand/bhand_finger_dist_link_convex.stl"/>
      </geometry>
    </collision>
  </link>
  <joint name="wam/bhand/finger_3/med_joint" type="revolute">
    <parent link="wam/bhand/bhand_palm_link"/>
    <child link="wam/bhand/finger_3/med_link"/>
    <origin rpy="1.57079632679 0 1.57079632679" xyz="0 0.05 0.0754"/>
    <axis xyz="0 0 1"/>
    <limit effort="5" lower="0" upper="2.44346095279" velocity="5.00"/>
    <dynamics damping="1.5" friction="1"/>
  </joint>
  <gazebo reference="wam/bhand/finger_3/med_joint">
    <provideFeedback>true</provideFeedback>
    <implicitSpringDamper>true</implicitSpringDamper>
  </gazebo>
  <gazebo reference="wam/bhand/finger_3/med_link">
    <mu1>0.8</mu1>
    <mu2>0.8</mu2>
    <selfCollide>true</selfCollide>
  </gazebo>
  <link name="wam/bhand/finger_3/med_link">
    <inertial>
      <origin xyz="0.023133 0.00078642 0.00052792"/>
      <mass value="0.062139"/>
      <inertia ixx="4.872e-006" ixy="1.7103e-006" ixz="3.4041e-008" iyy="7.6588e-005" iyz="2.3133e-008" izz="7.7733e-005"/>
    </inertial>
    <visual>
      <material name="WAMGrey">
        <color rgba="0.9 0.9 0.9 0.0"/>
      </material>
      <geometry>
        <mesh filename="package://barrett_model/models/sw_meshes/bhand/bhand_finger_med_link_fine.stl"/>
      </geometry>
    </visual>
    <collision>
      <geometry>
        <mesh filename="package://barrett_model/models/sw_meshes/bhand/bhand_finger_med_link_convex.stl"/>
      </geometry>
    </collision>
  </link>
  <joint name="wam/bhand/finger_3/dist_joint" type="revolute">
    <parent link="wam/bhand/finger_3/med_link"/>
    <child link="wam/bhand/finger_3/dist_link"/>
    <origin rpy="0 0 0" xyz="0.06994 0.003 0.0"/>
    <axis xyz="0 0 1"/>
    <limit effort="5" lower="0" upper="0.837758040957" velocity="5.00"/>
    <dynamics damping="1.5" friction="1"/>
  </joint>
  <gazebo reference="wam/bhand/finger_3/dist_joint">
    <provideFeedback>true</provideFeedback>
    <implicitSpringDamper>true</implicitSpringDamper>
  </gazebo>
  <gazebo reference="wam/bhand/finger_3/dist_link">
    <mu1>0.8</mu1>
    <mu2>0.8</mu2>
    <selfCollide>true</selfCollide>
  </gazebo>
  <link name="wam/bhand/finger_3/dist_link">
    <inertial>
      <origin xyz="0.022825 0.0010491 0.0004203"/>
      <mass value="0.041377"/>
      <inertia ixx="3.1582e-006" ixy="1.4308e-006" ixz="1.0106e-007" iyy="3.8376e-005" iyz="0" izz="3.7275e-005"/>
    </inertial>
    <visual>
      <material name="WAMGrey">
        <color rgba="0.9 0.9 0.9 0.0"/>
      </material>
      <geometry>
        <mesh filename="package://barrett_model/models/sw_meshes/bhand/bhand_finger_dist_link_fine.stl"/>
      </geometry>
    </visual>
    <collision>
      <geometry>
        <mesh filename="package://barrett_model/models/sw_meshes/bhand/bhand_finger_dist_link_convex.stl"/>
      </geometry>
    </collision>
  </link>
</robot>

